Workbook
Name AccionSobreActivo: Listas!$AC$3:$AC$6
Name AccionSobreActivo2: Listas!$AC$7:$AC$8
Name AccionSobreActivo3: Listas!$AC$9
Name AnalisisTecnico: Listas!$Y$3:$Y$4
Name AreaMinimaCIAI: Infraestructura!$AT$42:$AV$49
Name CD_calidad1: Listas!$H$17:$H$19
Name CD_calidad2: Listas!$H$20
Name CD_cobertura1: Listas!$H$21:$H$23
Name CD_cobertura2: Listas!$H$24
Name CI_calidad1.1: Listas!$M$17:$M$20
Name CI_calidad1.2: Listas!$M$21:$M$23
Name CI_calidad1.3: Listas!$M$24:$M$26
Name CI_calidad2.1: Listas!$M$27:$M$29
Name CI_cobertura1.1: Listas!$M$30:$M$33
Name CI_cobertura1.2: Listas!$M$34:$M$36
Name CI_cobertura1.3: Listas!$M$37:$M$39
Name CI_cobertura2.1: Listas!$M$40:$M$42
Name CumplimientoCondiciones: Listas!$W$3:$W$4
Name EstadoActual: Listas!$L$3:$L$6
Name ExposicionFragilidad: Listas!$AA$3:$AA$5
Name FactorProduccion: Listas!$AI$3:$AI$6
Name FuenteFinanciamiento: Listas!$AO$3:$AO$7
Name Impacto: Listas!$D$3:$D$7
Name Involucrados: Listas!$S$3:$S$6
Name MuroContencion: Listas!$N$3:$N$4
Name Naturaleza: Listas!$H$3:$H$6
Name NivelGobierno: Listas!$J$3:$J$5
Name Optimizar: Listas!$U$3:$U$5
Name PC_calidad: Listas!$F$17:$F$18
Name PC_cobertura: Listas!$F$19:$F$20
Name Probabilidad: Listas!$E$3:$E$7
Name Problematica: Listas!$D$16:$L$24
Name SaneamientoConProyecto: Listas!$AK$3:$AK$9
Name Si_No: Listas!$G$3:$G$4
Name SituacionSaneamientoLegal: Listas!$AE$3:$AE$8
Name TamañoCIAI: Infraestructura!$AQ$38:$AY$40
Name TipoCIAI: Listas!$P$3:$Q$10
Name TipoEjecucion: Listas!$AM$3:$AM$7
Name Titularidad: Listas!$AG$3:$AG$4
Name UBIGEO: UBIGEO!$A$3:$D$1876

Sheet Listas
D2: Impacto | E2: Probabilidad | G2: Si_No | H2: Naturaleza | J2: Nivel de gobierno | L2: Estado actual | N2: Muro de contención | P2: Tipo de CIAI | Q2: niño/as | S2: Involucrados | U2: Optimizar | W2: CumplimientoCondiciones | Y2: AnalisisTecnico | AA2: ExposicionFragilidad | AC2: AccionSobreActivo | AE2: SituacionSaneamientoLegal | AG2: Titularidad | AI2: FactorProduccion | AK2: SaneamientoConProyecto | AM2: TipoEjecucion | AO2: FuenteFinanciamiento
D3: 0.05 | E3: 0.9 | G3: Sí | H3: Mejoramiento | J3: Gobierno Nacional | L3: Bueno | N3: ML | P3: Tipo I-A | Q3: 20 | R3: 1 | S3: Cooperante | U3: EL CIAI existe, sin embargo, dadas las condiciones de la infraestructura, como factor de producción, no se puede optimizar la oferta actual. Para detalle, ver informe técnico de situación de infraestructura del CIAI | W3: Cumple | Y3: Se incluye en el PI | AA3: Bajo | AC3: Construcción | AE3: Inscrito en Registros Públicos a favor del PNCM | AG3: Propiedad del Estado | AI3: Infraestructura | AK3: Acta de facilitación de espacios físicos de bien inmueble, debidamente suscrita por el PNCM y el representante de la Institución Educativa, que contemplen espacios determinados dentro de las instalaciones de las Instituciones Educativas Públicas. | AM3: Administración directa | AO3: Recursos ordinarios
D4: 0.1 | E4: 0.7 | G4: No | H4: Ampliación | J4: Gobierno Regional | L4: Regular | N4: M3 | P4: Tipo I-B | Q4: 20 | R4: 2 | S4: Beneficiario | U4: El CIAI existe y se puede optimizar la oferta actual | W4: No Cumple | Y4: No se incluye en el PI | AA4: Medio | AC4: Reforzamiento | AE4: Caso Gobierno Regional: Resolución y/o acuerdo de consejo que aprueba la afectación a favor o transferencia a favor del PNCM | AG4: Propiedad de particulares (privados) | AI4: Mobiliario | AK4: Certificado literal de la partida registral donde se encuentre inscrita la Afectación en Uso a favor del Programa Nacional Cuna Más – PNCM. | AM4: Administración indirecta – por contrata | AO4: Recursos directamente recaudados | AP4: Marcar
D5: 0.2 | E5: 0.5 | H5: Mejoramiento y ampliación | J5: Gobierno Local | L5: Malo | P5: Tipo II-A | Q5: 32 | R5: 3 | S5: Oponente | AA5: Alto | AC5: Remodelación | AE5: Caso Municipalidad: Resolución de alcaldía y/o acuerdo de consejo que aprueba la transferencia o afectación en uso a favor del PNCM | AI5: Equipo | AK5: Constancia de Posesión otorgada por Municipalidad Distrital a favor del Programa Nacional Cuna Más. | AM5: Administración indirecta – Asociación Público Privado (APP) | AO5: Recursos por operaciones oficiales de crédito
D6: 0.4 | E6: 0.3 | H6: Recuperación | L6: No existe | P6: Tipo II-B | Q6: 40 | R6: 4 | S6: Perjudicado | AC6: Rehabilitación | AE6: Caso Comunidad: Acta de trasferencia o cesión en uso a favor del PNCM, o a favor de una municipalidad, o Gobierno Regional que posteriormente se comprometan a transferirlo a favor de PNCM. | AI6: Capacidades de Recursos Humanos | AK6: Contrato de Comodato suscrito entre el PNCM y el(los) propietario(s) del bien inmueble (Persona Natural), que contemplen el uso exclusivo del local para el Servicio de Cuidado Diurno. | AM6: Administración indirecta – Núcleo Ejecutor | AO6: Donaciones y transferencias
D7: 0.8 | E7: 0.1 | P7: Tipo III-A | Q7: 52 | R7: 5 | AC7: Adquisición | AE7: Carta de intención del propietario, declarando su voluntad de vender y se especifique el área y costo por m2, o una intención de donación | AK7: Convenio de Cesión/Afectación en Uso, suscrito entre el PNCM y una Entidad Pública (Municipalidad, Gobierno Regional, Ministerios entre otras) o privada (Asentamiento Humanos, Comités, Urbanizaciones, etc.); Entidades Religiosas, Sociedad Civiles Sin Fines de Lucro, Comunidades Campesinas y Nativas. | AM7: Administración indirecta – Ley 29230 (Obras por Impuestos) | AO7: Recursos determinados
P8: Tipo III-B | Q8: 60 | R8: 6 | AC8: Reposición | AE8: Acta de compromiso de la UEI de gestionar el Saneamiento Físico Legal del Terreno antes del inicio de la elaboración del Expediente Técnico | AK8: Resolución de Afectación en Uso del bien inmueble emitida por Autoridad Pública competente y con arreglo a Ley.
P9: Tipo IV-A | Q9: 72 | R9: 7 | AC9: Implementación de capacidades | AK9: Otra
P10: Tipo IV-B | Q10: 82 | R10: 8
D16: Problema central | E16: ID_PC | F16: Causas directas | G16: ID Causas directas | H16: Causas indirectas | J16: Objetivo central | K16: Medios de primer nivel | L16: Medios fundamentales | M16: Acciones | N16: Indicador | O16: Descripción | P16: Naturaleza
C17: Mejoramiento | D17: =+"Niños y niñas, entre 6 y 36 meses de edad, acceden a una inadecuada prestación del servicio de cuidado diurno en la localidad de "&'Unidad Productora'!L20&", distrito de "&'Unidad Productora'!J20&", provincia de "&'Unidad Productora'!H20&", departamento de "&'Unidad Productora'!E20 -> Niños y niñas, entre 6 y 36 meses de edad, acceden a una inadecuada prestación del servicio de cuidado diurno en la localidad de , distrito de , provincia de , departamento de | E17: PC_calidad | F17: Inadecuadas condiciones físicas para brindar el servicio de cuidado diurno | G17: CD_calidad1 | H17: Infraestructura del CIAI no cumple con los estándares de calidad | I17: CI_calidad1.1 | J17: =+"Niños y niñas, entre 6 y 36 meses de edad, acceden a una adecuada prestación del servicio de cuidado diurno en la localidad de "&'Unidad Productora'!L20&", distrito de "&'Unidad Productora'!J20&", provincia de "&'Unidad Productora'!H20&", departamento de "&'Unidad Productora'!E20 -> Niños y niñas, entre 6 y 36 meses de edad, acceden a una adecuada prestación del servicio de cuidado diurno en la localidad de , distrito de , provincia de , departamento de | K17: Adecuadas condiciones físicas para brindar el servicio de cuidado diurno | L17: Infraestructura del CIAI cumple con los estándares de calidad | M17: Acción 1.1.1. Construcción de infraestructura del CIAI, que cumpla con los estándares de calidad | N17: Porcentaje de centros infantiles de atención integral que brindan el servicio de cuidado integral en condición inadecuada. (PCIAICI) | O17: El indicador representa la proporción de centros infantiles de atención integral (CIAI) respecto al total a nivel nacional, que tienen al menos un factor productivo que no se encuentra de acuerdo con lo establecido en la normativa del PNCM | P17: Mejoramiento
C18: Ampliación | D18: =+"Niños y niñas, entre 6 y 36 meses de edad, acceden a una inadecuada prestación del servicio de cuidado diurno en la localidad de "&'Unidad Productora'!L20&", distrito de "&'Unidad Productora'!J20&", provincia de "&'Unidad Productora'!H20&", departamento de "&'Unidad Productora'!E20 -> Niños y niñas, entre 6 y 36 meses de edad, acceden a una inadecuada prestación del servicio de cuidado diurno en la localidad de , distrito de , provincia de , departamento de | E18: PC_calidad | F18: Insuficiente capacidad para la gestión y atención del servicio de cuidado diurno | G18: CD_calidad2 | H18: Equipos del CIAI no cumplen con los estándares de calidad | I18: CI_calidad1.2 | J18: =+"Niños y niñas, entre 6 y 36 meses de edad, acceden a una adecuada prestación del servicio de cuidado diurno en la localidad de "&'Unidad Productora'!L20&", distrito de "&'Unidad Productora'!J20&", provincia de "&'Unidad Productora'!H20&", departamento de "&'Unidad Productora'!E20 -> Niños y niñas, entre 6 y 36 meses de edad, acceden a una adecuada prestación del servicio de cuidado diurno en la localidad de , distrito de , provincia de , departamento de | K18: Suficiente capacidad para la gestión y atención del servicio de cuidado diurno | L18: Equipos del CIAI cumplen con los estándares de calidad | M18: Acción 1.1.2 Reforzamiento de infraestructura del CIAI, que cumpla con los estándares de calidad | N18: Porcentaje de centros infantiles de atención integral que brindan el servicio de cuidado integral en condición inadecuada. (PCIAICI) | O18: El indicador representa la proporción de centros infantiles de atención integral (CIAI) respecto al total a nivel nacional, que tienen al menos un factor productivo que no se encuentra de acuerdo con lo establecido en la normativa del PNCM | P18: Ampliación
C19: Mejoramiento y ampliación | D19: =+"Niños y niñas, entre 6 y 36 meses de edad, acceden a una inadecuada prestación del servicio de cuidado diurno en la localidad de "&'Unidad Productora'!L20&", distrito de "&'Unidad Productora'!J20&", provincia de "&'Unidad Productora'!H20&", departamento de "&'Unidad Productora'!E20 -> Niños y niñas, entre 6 y 36 meses de edad, acceden a una inadecuada prestación del servicio de cuidado diurno en la localidad de , distrito de , provincia de , departamento de | E19: PC_calidad | F19: Condiciones físicas inexistentes para brindar el servicio de cuidado diurno | G19: CD_cobertura1 | H19: Mobiliario del CIAI no cumple con los estándares de calidad | I19: CI_calidad1.3 | J19: =+"Niños y niñas, entre 6 y 36 meses de edad, acceden a una adecuada prestación del servicio de cuidado diurno en la localidad de "&'Unidad Productora'!L20&", distrito de "&'Unidad Productora'!J20&", provincia de "&'Unidad Productora'!H20&", departamento de "&'Unidad Productora'!E20 -> Niños y niñas, entre 6 y 36 meses de edad, acceden a una adecuada prestación del servicio de cuidado diurno en la localidad de , distrito de , provincia de , departamento de | K19: Condiciones físicas existentes para brindar el servicio de cuidado diurno | L19: Mobiliario del CIAI cumple con los estándares de calidad | M19: Acción 1.1.3 Remodelación de infraestructura del CIAI, que cumpla con los estándares de calidad | N19: Porcentaje de centros infantiles de atención integral que brindan el servicio de cuidado integral en condición inadecuada. (PCIAICI) | O19: El indicador representa la proporción de centros infantiles de atención integral (CIAI) respecto al total a nivel nacional, que tienen al menos un factor productivo que no se encuentra de acuerdo con lo establecido en la normativa del PNCM | P19: Mejoramiento y ampliación
C20: Recuperación | D20: =+"Niños y niñas, entre 6 y 36 meses de edad, acceden a una inadecuada prestación del servicio de cuidado diurno en la localidad de "&'Unidad Productora'!L20&", distrito de "&'Unidad Productora'!J20&", provincia de "&'Unidad Productora'!H20&", departamento de "&'Unidad Productora'!E20 -> Niños y niñas, entre 6 y 36 meses de edad, acceden a una inadecuada prestación del servicio de cuidado diurno en la localidad de , distrito de , provincia de , departamento de | E20: PC_calidad | F20: Limitadas capacidades para la gestión y para la atención del servicio de cuidado diurno | G20: CD_cobertura2 | H20: Insuficiente capacitación de recursos humanos que operan en el CIAI | I20: CI_calidad2.1 | J20: =+"Niños y niñas, entre 6 y 36 meses de edad, acceden a una adecuada prestación del servicio de cuidado diurno en la localidad de "&'Unidad Productora'!L20&", distrito de "&'Unidad Productora'!J20&", provincia de "&'Unidad Productora'!H20&", departamento de "&'Unidad Productora'!E20 -> Niños y niñas, entre 6 y 36 meses de edad, acceden a una adecuada prestación del servicio de cuidado diurno en la localidad de , distrito de , provincia de , departamento de | K20: Adecuadas capacidades para la gestión y para la atención del servicio de cuidado diurno | L20: Suficientes capacidades organizacionales de los recursos humanos que operan en el CIAI | M20: Acción 1.1.4 Rehabilitación de infraestructura del CIAI, que cumpla con los estándares de calidad | N20: Porcentaje de centros infantiles de atención integral que brindan el servicio de cuidado integral en condición inadecuada. (PCIAICI) | O20: El indicador representa la proporción de centros infantiles de atención integral (CIAI) respecto al total a nivel nacional, que tienen al menos un factor productivo que no se encuentra de acuerdo con lo establecido en la normativa del PNCM | P20: Recuperación
C21: Creación | D21: =+"Niños y niñas, entre 6 y 36 meses de edad, no acceden al servicio de cuidado diurno en la localidad de "&'Unidad Productora'!L20&", distrito de "&'Unidad Productora'!J20&", provincia de "&'Unidad Productora'!H20&", departamento de "&'Unidad Productora'!E20 -> Niños y niñas, entre 6 y 36 meses de edad, no acceden al servicio de cuidado diurno en la localidad de , distrito de , provincia de , departamento de | E21: PC_cobertura | J21: =+"Niños y niñas, entre 6 y 36 meses de edad, acceden al servicio de cuidado diurno en la localidad de "&'Unidad Productora'!L20&", distrito de "&'Unidad Productora'!J20&", provincia de "&'Unidad Productora'!H20&", departamento de "&'Unidad Productora'!E20 -> Niños y niñas, entre 6 y 36 meses de edad, acceden al servicio de cuidado diurno en la localidad de , distrito de , provincia de , departamento de | L21: Se cuenta con infraestructura para brindar el servicio | M21: Acción 1.2.1 Adquisición y/o reposición de equipos para el CIAI, de acuerdo a los estándares definidos por el PNCM. | N21: Porcentaje de centros infantiles de atención integral por implementar. (PCIAIPI) | O21: El indicador determina el déficit de Centros Infantiles de Cuidado Diurno para cubrir las necesidades de niños y niñas entre 6 y 36 meses de edad, que viven en zonas de pobreza y pobreza extrema, considerados como población objetivo, según los criterios de focalización del PNCM. | P21: Creación
L22: Se cuenta con equipos para brindar el servicio
L23: Se cuenta con mobiliario para brindar el servicio
L24: Suficientes capacidades de los recursos humanos para el cuidado integral | M24: Acción 1.3.1 Adquisición y/o reposición de mobiliario para el CIAI, de acuerdo a los estándares definidos por el PNCM.
M27: Acción 2.1.1 Implementación de capacidades humanas a los actores comunitarios que operan el CIAI
M28: Acción 2.1.2 Implementación de capacidades organizacionales a los actores comunitarios que operarán el CIAI.
M30: Acción 1.1.1. Construcción de infraestructura del CIAI, que cumpla con los estándares de calidad
M31: Acción 1.1.2 Reforzamiento de infraestructura del CIAI, que cumpla con los estándares de calidad
M32: Acción 1.1.3 Remodelación de infraestructura del CIAI, que cumpla con los estándares de calidad
M33: Acción 1.1.4 Rehabilitación de infraestructura del CIAI, que cumpla con los estándares de calidad
M34: Acción 1.2.1 Adquisición y/o reposición de equipos para el CIAI, de acuerdo a los estándares definidos por el PNCM.
M37: Acción 1.3.1 Adquisición y/o reposición de mobiliario para el CIAI, de acuerdo a los estándares definidos por el PNCM.
M40: Acción 2.1.1 Implementación de capacidades organizacionales a los actores comunitarios que operarán el CIAI
M41: Acción 2.1.2 cobertura
M42: Acción 2.1.3 cobertura
D44: =+VLOOKUP('Problema-Objetivo'!B8,D17:E21,2,FALSE) -> #N/A
C48: =+VLOOKUP('Problema-Objetivo'!F12,$H$17:$I$24,2,FALSE) -> #N/A | D48: =+VLOOKUP('Problema-Objetivo'!B12,F17:G20,2,FALSE) -> #N/A
C49: =+VLOOKUP('Problema-Objetivo'!F13,$H$17:$I$24,2,FALSE) -> #N/A
C50: =+VLOOKUP('Problema-Objetivo'!F14,$H$17:$I$24,2,FALSE) -> #N/A
C51: =+VLOOKUP('Problema-Objetivo'!F15,$H$17:$I$24,2,FALSE) -> #N/A | D51: =+VLOOKUP('Problema-Objetivo'!B15,F17:G20,2,FALSE) -> #N/A
J54: Caso Gobierno Regional: Resolución y/o acuerdo de consejo que aprueba la afectación a favor o transferencia a favor del PNCM
J55: Caso Municipalidad: Resolución de alcaldía y/o acuerdo de consejo que aprueba la transferencia o afectación en uso
J56: Caso Comunidad: Acta de trasferencia o cesión en uso a favor del PNCM, o a favor de una municipalidad, o Gobierno Regional que posteriormente se comprometan a transferirlo a favor de PNCM.
J57: Acta de compromiso de la UEI de gestionar el Saneamiento Físico Legal del Terreno antes del inicio de la elaboración del Expediente Técnico

Sheet Infraestructura
A1: Anexo 01: Centro Infantil de Atención Integral, Tipo I-A | F1: Anexo 02: Centro Infantil de Atención Integral, Tipo I-B | K1: Anexo 03: Centro Infantil de Atención Integral, Tipo II-A | P1: Anexo 04: Centro Infantil de Atención Integral, Tipo II-B | BI1: Equivalencias: activos estratégicos y ambientes del CIAI
U2: Anexo 05: Centro Infantil de Atencion Integral, Tipo III-A | Z2: Anexo 06: Centro Infantil de Atencion Integral, Tipo III-B | AE2: Anexo 07: Centro Infantil de Atencion Integral, Tipo IV-A | AJ2: Anexo 08: Centro Infantil de Atencion Integral, Tipo IV-B | AR2: Tipo I-A | AS2: Tipo I-B | AT2: Tipo II-A | AU2: Tipo II-B | AV2: Tipo III-A | AW2: Tipo III-B | AX2: Tipo IV-A | AY2: Tipo IV-B | BB2: SA | BI2: Activo estratégico | BJ2: Descripción | BK2: Ambiente según directiva | BL2: =+AR2 -> Tipo I-A | BM2: =+AS2 -> Tipo I-B | BN2: =+AT2 -> Tipo II-A | BO2: =+AU2 -> Tipo II-B | BP2: =+AV2 -> Tipo III-A | BQ2: =+AW2 -> Tipo III-B | BR2: =+AX2 -> Tipo IV-A | BS2: =+AY2 -> Tipo IV-B
B3: ESPACIO | C3: Área Mínima (m2) | D3: Número de niñas/os | G3: ESPACIO | H3: Área Mínima (m2) | I3: Número de niñas/os | L3: ESPACIO | M3: Área Mínima (m2) | N3: Número de niñas/os | Q3: ESPACIO | R3: Área Mínima (m2) | S3: Número de niñas/os | V3: ESPACIO | W3: Área Minima (m2) | X3: Número de niñas/os | AA3: ESPACIO | AB3: Área Mínima (m2) | AC3: Número de niñas/os | AF3: ESPACIO | AG3: Área Minima (m2) | AH3: Número de niñas/os | AK3: ESPACIO | AL3: Área Mínima (m2) | AM3: Número de niñas/os | AO3: Área | AP3: ID | AQ3: Ambiente | AR3: M2 | AS3: M2 | AT3: M2 | AU3: M2 | AV3: M2 | AW3: M2 | AX3: M2 | AY3: M2 | BB3: Área de preparación (cocina) | BE3: 20 | BI3: Sala de cuidado diurno | BJ3: =+'Análisis Técnico'!G56 -> Espacio físico donde se brinda la atención integral a los niños (bebes, gateadores y caminantes), en este espacio se encuentran organizados las áreas de juego y cuidado. | BK3: Sala mixta | BL3: =+AR4 -> 50.4 | BM3: =+AS4 -> 50.4 | BN3: =+AT4 -> 50.4 | BO3: =+AU4 -> 50.4 | BP3: =+AV4 -> 50.4 | BQ3: =+AW4 -> 50.4 | BR3: =+AX4 -> 50.4 | BS3: =+AY4 -> 50.4
A4: CIUDADANO DIURNO | B4: SALA MIXTA 1 | C4: 50.4 | D4: 20 | F4: CIUDADANO DIURNO | G4: SALA MIXTA 1 | H4: 50.4 | I4: 20 | K4: CIUDADANO DIURNO | L4: SALA MIXTA 1 | M4: 50.4 | N4: 20 | P4: CIUDADANO DIURNO | Q4: SALA MIXTA 1 | R4: 50.4 | S4: 20 | U4: CUIDADO DIURNO | V4: SALA MIXTA 1 | W4: 50.4 | X4: 20 | Z4: CUIDADO DIURNO | AA4: SALA MIXTA 1 | AB4: 50.4 | AC4: 20 | AE4: CUIDADO DIURNO | AF4: SALA MIXTA 1 | AG4: 50.4 | AH4: 20 | AJ4: CUIDADO DIURINO | AK4: SALA MIXTA 1 | AL4: 50.4 | AM4: 20 | AO4: Cuidado diurno | AP4: A1 | AQ4: SALA MIXTA 1 | AR4: =+_xlfn.IFNA(VLOOKUP($AQ4,$B$4:$C$30,2,FALSE),"") -> 50.4 | AS4: =+_xlfn.IFNA(VLOOKUP($AQ4,$G$4:$H$30,2,FALSE),"") -> 50.4 | AT4: =+_xlfn.IFNA(VLOOKUP($AQ4,$L$4:$M$30,2,FALSE),"") -> 50.4 | AU4: =+_xlfn.IFNA(VLOOKUP($AQ4,$Q$4:$R$30,2,FALSE),"") -> 50.4 | AV4: =+_xlfn.IFNA(VLOOKUP($AQ4,$V$4:$W$30,2,FALSE),"") -> 50.4 | AW4: =+_xlfn.IFNA(VLOOKUP($AQ4,$AA$4:$AB$30,2,FALSE),"") -> 50.4 | AX4: =+_xlfn.IFNA(VLOOKUP($AQ4,$AF$4:$AG$30,2,FALSE),"") -> 50.4 | AY4: =+_xlfn.IFNA(VLOOKUP($AQ4,$AK$4:$AL$30,2,FALSE),"") -> 50.4 | BB4: Almacén de alimentos | BE4: 9 | BI4: Sala de usos múltiples | BJ4: =+'Análisis Técnico'!G57 -> Espacio donde se realizan los juegos de los niños y actividades lúdicas, este espacio también es utilizado como comedor para la atención alimentaria de los niños . | BK4: Plaza de usos múltiples / comedor | BL4: =+AR16 -> 0 | BM4: =+AS16 -> 15 | BN4: =+AT16 -> 24 | BO4: =+AU16 -> 30 | BP4: =+AV16 -> 39 | BQ4: =+AW16 -> 45 | BR4: =+AX16 -> 54 | BS4: =+AY16 -> 60
B5: Servicios Higiénicos (un inodoro y un lavatorio por cada 8 niños) incluye Pañalera | C5: 8.2 | D5: - | G5: Servicios Higiénicos (un inodoro y un lavatorio por cada 8 niños) incluye Pañalera | H5: 8.2 | I5: - | L5: Servicios Higiénicos (un inodoro y un lavatorio por cada 8 niños) incluye Pañalera | M5: 8.2 | N5: - | Q5: Servicios Higiénicos (un inodoro y un lavatorio por cada 8 niños) incluye Pañalera | R5: 8.2 | S5: - | V5: Servicios Higiénicos (un inodoro y un lavatorio por cada 8 niños) incluye Peñalera | W5: 8.2 | X5: - | AA5: Servicios Higiénicos (un inodoro y un lavatorio por cada 8 niños) incluye Pañalera | AB5: 8.2 | AC5: - | AF5: Servicios Higiénicos (un inodoro y un lavatorio por cada 8 niños) incluye Pañalera | AG5: 8.2 | AH5: - | AK5: Servicios Higiénicos (un inodoro y un lavatorio por cada 8 niños) incluye Pañalera | AL5: 8.2 | AM5: - | AO5: Cuidado diurno | AP5: A2 | AQ5: Servicios Higiénicos (un inodoro y un lavatorio por cada 8 niños) incluye Pañalera | AR5: =+_xlfn.IFNA(VLOOKUP($AQ5,$B$4:$C$30,2,FALSE),"") -> 8.2 | AS5: =+_xlfn.IFNA(VLOOKUP($AQ5,$G$4:$H$30,2,FALSE),"") -> 8.2 | AT5: =+_xlfn.IFNA(VLOOKUP($AQ5,$L$4:$M$30,2,FALSE),"") -> 8.2 | AU5: =+_xlfn.IFNA(VLOOKUP($AQ5,$Q$4:$R$30,2,FALSE),"") -> 8.2 | AV5: =+_xlfn.IFNA(VLOOKUP($AQ5,$V$4:$W$30,2,FALSE),"") -> 8.2 | AW5: =+_xlfn.IFNA(VLOOKUP($AQ5,$AA$4:$AB$30,2,FALSE),"") -> 8.2 | AX5: =+_xlfn.IFNA(VLOOKUP($AQ5,$AF$4:$AG$30,2,FALSE),"") -> 8.2 | AY5: =+_xlfn.IFNA(VLOOKUP($AQ5,$AK$4:$AL$30,2,FALSE),"") -> 8.2 | BB5: Hall de servicio alimentario | BE5: 2.5 | BI5: Ambiente de recreación activa | BJ5: =+'Análisis Técnico'!G58 -> Espacio exterior destinado al encuentro y recreación activa entre niñas y niños, cuidadoras, así como de familias usuarias, organizado y equipado para las actividades. | BK5: Espacio de juego al aire libre | BL5: =+AR24 -> 20.16 | BM5: =+AS24 -> 20.16 | BN5: =+AT24 -> 32.64 | BO5: =+AU24 -> 40.32 | BP5: =+AV24 -> 52.8 | BQ5: =+AW24 -> 60.48 | BR5: =+AX24 -> 72.96 | BS5: =+AY24 -> 80.64
B6: Closet para colchoneta | C6: 1 | D6: - | G6: Closet para colchoneta | H6: 1 | I6: - | L6: Closet para colchoneta | M6: 1 | N6: - | Q6: Closet para colchoneta | R6: 1 | S6: - | V6: Closet para colchoneta | W6: 1 | X6: - | AA6: Closet para colchoneta | AB6: 1 | AC6: - | AF6: Closet para colchoneta | AG6: 1 | AH6: - | AK6: Closet para colchoneta | AL6: 1 | AM6: - | AO6: Cuidado diurno | AP6: A3 | AQ6: Closet para colchoneta | AR6: =+_xlfn.IFNA(VLOOKUP($AQ6,$B$4:$C$30,2,FALSE),"") -> 1 | AS6: =+_xlfn.IFNA(VLOOKUP($AQ6,$G$4:$H$30,2,FALSE),"") -> 1 | AT6: =+_xlfn.IFNA(VLOOKUP($AQ6,$L$4:$M$30,2,FALSE),"") -> 1 | AU6: =+_xlfn.IFNA(VLOOKUP($AQ6,$Q$4:$R$30,2,FALSE),"") -> 1 | AV6: =+_xlfn.IFNA(VLOOKUP($AQ6,$V$4:$W$30,2,FALSE),"") -> 1 | AW6: =+_xlfn.IFNA(VLOOKUP($AQ6,$AA$4:$AB$30,2,FALSE),"") -> 1 | AX6: =+_xlfn.IFNA(VLOOKUP($AQ6,$AF$4:$AG$30,2,FALSE),"") -> 1 | AY6: =+_xlfn.IFNA(VLOOKUP($AQ6,$AK$4:$AL$30,2,FALSE),"") -> 1 | BB6: Espacio para cestos | BE6: 1 | BI6: Ambiente de servicios generales | BJ6: =+'Análisis Técnico'!G59 -> Espacios destinados a actividades de apoyo a las funciones que se realizan en el establecimiento, tales como: área para tanque séptico y pozo percolador, depósito de materiales, patio de servicio, cuarto de tableros, caseta de vigilancia, área de guardado para coches para bebes, espacio de cambio de pañales). | BK6: Servicios complementarios (Área de lavado de vajilla; Servicios higiénicos de adultos (1/2 baño acondicionado para personas con discapacidad); Depósito de material educativo; Cubículo de Bomba de Agua; Closet de Limpieza; Lavandería; Patio Tendal) | BL6: =+AR17+AR18+AR19+AR20+AR21+AR22+AR23 -> 20.52 | BM6: =+AS17+AS18+AS19+AS20+AS21+AS22+AS23 -> 22.32 | BN6: =+AT17+AT18+AT19+AT20+AT21+AT22+AT23 -> 25.32 | BO6: =+AU17+AU18+AU19+AU20+AU21+AU22+AU23 -> 25.32 | BP6: =+AV17+AV18+AV19+AV20+AV21+AV22+AV23 -> 28.32 | BQ6: =+AW17+AW18+AW19+AW20+AW21+AW22+AW23 -> 28.32 | BR6: =+AX17+AX18+AX19+AX20+AX21+AX22+AX23 -> 31.32 | BS6: =+AY17+AY18+AY19+AY20+AY21+AY22+AY23 -> 31.32
A7: SERVICIOS COMPLEMENTARIOS | B7: Área de lavado de vajilla | C7: 1.8 | D7: - | G7: PLAZA DE USOS MULTIPLES/COMEDOR (mínimo 0.75 m2 por total de niños) | H7: 15 | L7: SALA MIXTA 2 | M7: 31.2 | N7: 12 | Q7: SALA MIXTA 2 | R7: 50.4 | S7: 20 | V7: SALA MIXTA 2 | W7: 50.4 | X7: 20 | AA7: SALA MIXTA 2 | AB7: 50.4 | AC7: 20 | AF7: SALA MIXTA 2 | AG7: 50.4 | AH7: 20 | AK7: SALA MIXTA 2 | AL7: 50.4 | AM7: 20 | AO7: Cuidado diurno | AP7: A4 | AQ7: SALA MIXTA 2 | AT7: =+_xlfn.IFNA(VLOOKUP($AQ7,$L$4:$M$30,2,FALSE),"") -> 31.2 | AU7: =+_xlfn.IFNA(VLOOKUP($AQ7,$Q$4:$R$30,2,FALSE),"") -> 50.4 | AV7: =+_xlfn.IFNA(VLOOKUP($AQ7,$V$4:$W$30,2,FALSE),"") -> 50.4 | AW7: =+_xlfn.IFNA(VLOOKUP($AQ7,$AA$4:$AB$30,2,FALSE),"") -> 50.4 | AX7: =+_xlfn.IFNA(VLOOKUP($AQ7,$AF$4:$AG$30,2,FALSE),"") -> 50.4 | AY7: =+_xlfn.IFNA(VLOOKUP($AQ7,$AK$4:$AL$30,2,FALSE),"") -> 50.4 | BB7: Vestidor para socias de cocina | BE7: 2.5 | BI7: Ambiente de preparación y expendio de alimentos | BJ7: =+'Análisis Técnico'!G60 -> Espacio físico utilizado para la preparación de raciones alimenticias de los usuarios. | BK7: Servicio alimentario (Área de preparación (cocina); Vestidor para socias de cocina; Servicios higiénicos de adultos (baño completo); Closet de limpieza; Lavadero; Cubículo de bomba de agua) | BL7: =+BE3+BE7+BE8+BE9+BE10+BE11 -> 28.92 | BM7: =+BL7 -> 28.92 | BN7: =+BM7 -> 28.92 | BO7: =+BN7 -> 28.92 | BP7: =+BO7 -> 28.92 | BQ7: =+BP7 -> 28.92 | BR7: =+BQ7 -> 28.92 | BS7: =+BR7 -> 28.92
B8: Servicios higiénicos de adultos (1/2 baño acondicionado para personas con discapacidad) | C8: 4 | D8: - | F8: SERVICIOS COMPLEMENTARIOS | G8: Área de lavado de vajilla | H8: 2.7 | I8: - | L8: Servicios Higiénicos (un inodoro y un lavatorio por cada 8 niños) incluye Pañalera | M8: 6.4 | N8: - | Q8: Servicios Higiénicos (un inodoro y un lavatorio por cada 8 niños) incluye Pañalera | R8: 8.2 | S8: - | V8: Servicios Higiénicos (un inodoro y un lavatorio por cada 8 niños) incluye Pañalera | W8: 8.2 | X8: - | AA8: Servicios Higiénicos (un inodoro y un lavatorio por cada 8 niños) incluye Pañalera | AB8: 8.2 | AC8: - | AF8: Servicios Higiénicos (un inodoro y un lavatorio por cada 8 niños) incluye Pañalera. | AG8: 8.2 | AH8: - | AK8: Servicios Higiénicos (un inodoro y un lavatorio por cada 8 niños) incluye Pañalera | AL8: 8.2 | AM8: - | AO8: Cuidado diurno | AP8: A5 | AQ8: Servicios Higiénicos (un inodoro y un lavatorio por cada 8 niños) incluye Pañalera | AT8: =+M8 -> 6.4 | AU8: =+_xlfn.IFNA(VLOOKUP($AQ8,$Q$4:$R$30,2,FALSE),"") -> 8.2 | AV8: =+_xlfn.IFNA(VLOOKUP($AQ8,$V$4:$W$30,2,FALSE),"") -> 8.2 | AW8: =+_xlfn.IFNA(VLOOKUP($AQ8,$AA$4:$AB$30,2,FALSE),"") -> 8.2 | AX8: =+_xlfn.IFNA(VLOOKUP($AQ8,$AF$4:$AG$30,2,FALSE),"") -> 8.2 | AY8: =+_xlfn.IFNA(VLOOKUP($AQ8,$AK$4:$AL$30,2,FALSE),"") -> 8.2 | BB8: Servicios higiénicos de adultos (baño completo) | BE8: 3 | BI8: Almacén | BJ8: =+'Análisis Técnico'!G61 -> Espacio físico destinado para el acopio de los insumos alimenticios dentro de la cadena de suministros. | BK8: Almacén de alimentos; Hall de servicio alimentario; Espacio para cestos; | BL8: =+BE4+BE5+BE6 -> 12.5 | BM8: =+BL8 -> 12.5 | BN8: =+BM8 -> 12.5 | BO8: =+BN8 -> 12.5 | BP8: =+BO8 -> 12.5 | BQ8: =+BP8 -> 12.5 | BR8: =+BQ8 -> 12.5 | BS8: =+BR8 -> 12.5
B9: Depósito de material educativo | C9: 3 | D9: - | G9: Servicios higiénicos de adultos (1/2 baño acondicionado para personas con discapacidad) | H9: 4 | I9: - | L9: Closet para colchoneta | M9: 1 | N9: - | Q9: Closet para colchoneta | R9: 1 | S9: - | V9: Closet para colchoneta | W9: 1 | X9: - | AA9: Closet para colchoneta | AB9: 1 | AC9: - | AF9: Closet para colchoneta | AG9: 1 | AH9: - | AK9: Closet para colchoneta | AL9: 1 | AM9: - | AO9: Cuidado diurno | AP9: A6 | AQ9: Closet para colchoneta | AT9: =+_xlfn.IFNA(VLOOKUP($AQ9,$L$4:$M$30,2,FALSE),"") -> 1 | AU9: =+_xlfn.IFNA(VLOOKUP($AQ9,$Q$4:$R$30,2,FALSE),"") -> 1 | AV9: =+_xlfn.IFNA(VLOOKUP($AQ9,$V$4:$W$30,2,FALSE),"") -> 1 | AW9: =+_xlfn.IFNA(VLOOKUP($AQ9,$AA$4:$AB$30,2,FALSE),"") -> 1 | AX9: =+_xlfn.IFNA(VLOOKUP($AQ9,$AF$4:$AG$30,2,FALSE),"") -> 1 | AY9: =+_xlfn.IFNA(VLOOKUP($AQ9,$AK$4:$AL$30,2,FALSE),"") -> 1 | BB9: Closet de limpieza | BE9: 0.72 | BI9: Cerco perimétrico | BJ9: =+'Análisis Técnico'!G62 -> Activo para la protección de la unidad productora. Elemento fijo y seguro que rodea y delimita la propiedad o sus sectores. Cuenta con espacios de acceso al interior del mismo.
B10: Cubículo de Bomba de Agua | C10: 1.2 | D10: - | G10: Depósito de material educativo | H10: 3 | I10: - | L10: PLAZA DE USOS MULTIPLES/COMEDOR (mínimo 0.75 m2 por total de niños) | M10: 24 | N10: - | Q10: PLAZA DE USOS MULTIPLES/COMEDOR (mínimo 0.75 m2 por total de niños) | R10: 30 | S10: - | V10: SALA MIXTA 3 | W10: 31.2 | X10: 12 | AA10: SALA MIXTA 3 | AB10: 50.4 | AC10: 20 | AF10: SALA MIXTA 3 | AG10: 50.4 | AH10: 20 | AK10: SALA MIXTA 3 | AL10: 50.4 | AM10: 20 | AO10: Cuidado diurno | AP10: A7 | AQ10: SALA MIXTA 3 | AV10: =+_xlfn.IFNA(VLOOKUP($AQ10,$V$4:$W$30,2,FALSE),"") -> 31.2 | AW10: =+_xlfn.IFNA(VLOOKUP($AQ10,$AA$4:$AB$30,2,FALSE),"") -> 50.4 | AX10: =+_xlfn.IFNA(VLOOKUP($AQ10,$AF$4:$AG$30,2,FALSE),"") -> 50.4 | AY10: =+_xlfn.IFNA(VLOOKUP($AQ10,$AK$4:$AL$30,2,FALSE),"") -> 50.4 | BB10: Lavadero | BE10: 1.5 | BI10: Muro de contención | BJ10: =+'Análisis Técnico'!G63 -> Activo para la protección de la unidad productora. Estructura rígida destinada a contener masas de suelo u otros materiales sueltos proporcionando estabilidad.
B11: Closet de Limpieza | C11: 0.72 | D11: - | G11: Cubículo de Bomba de Agua | H11: 1.2 | I11: - | K11: SERVICIOS COMPLEMENTARIOS | L11: Área de lavado de vajilla | M11: 2.7 | N11: - | P11: SERVICIOS COMPLEMENTARIOS | Q11: Área de lavado de vajilla | R11: 2.7 | S11: - | V11: Servicios Higiénicos (un inodoro y un lavatono por cada 8 ninos) incluye Pañalera | W11: 6.4 | AA11: Servicios Higiénicos (un inodoro y un lavatono por cada 8 ninos) incluye Pañalera | AB11: 8.2 | AC11: - | AF11: Servicios Higiénicos (un inodoro y un lavatono por cada 8 ninos) incluye Pañalera | AG11: 8.2 | AH11: - | AK11: Servicios Higiénicos (un inodoro y un lavatono por cada 8 ninos) incluye Pañalera | AL11: 8.2 | AM11: - | AO11: Cuidado diurno | AP11: A8 | AQ11: Servicios Higiénicos (un inodoro y un lavatono por cada 8 ninos) incluye Pañalera | AV11: =+_xlfn.IFNA(VLOOKUP($AQ11,$V$4:$W$30,2,FALSE),"") -> 6.4 | AW11: =+_xlfn.IFNA(VLOOKUP($AQ11,$AA$4:$AB$30,2,FALSE),"") -> 8.2 | AX11: =+_xlfn.IFNA(VLOOKUP($AQ11,$AF$4:$AG$30,2,FALSE),"") -> 8.2 | AY11: =+_xlfn.IFNA(VLOOKUP($AQ11,$AK$4:$AL$30,2,FALSE),"") -> 8.2 | BB11: Cubículo de bomba de agua | BE11: 1.2 | BI11: Otros ambientes complementarios | BJ11: =+'Análisis Técnico'!G64 -> 0 | BK11: Servicios higiénicos; clóset | BL11: =+AR5+AR6+AR8+AR9+AR11+AR12+AR14+AR15 -> 9.2 | BM11: =+AS5+AS6+AS8+AS9+AS11+AS12+AS14+AS15 -> 9.2 | BN11: =+AT5+AT6+AT8+AT9+AT11+AT12+AT14+AT15 -> 16.6 | BO11: =+AU5+AU6+AU8+AU9+AU11+AU12+AU14+AU15 -> 18.4 | BP11: =+AV5+AV6+AV8+AV9+AV11+AV12+AV14+AV15 -> 25.8 | BQ11: =+AW5+AW6+AW8+AW9+AW11+AW12+AW14+AW15 -> 27.6 | BR11: =+AX5+AX6+AX8+AX9+AX11+AX12+AX14+AX15 -> 35 | BS11: =+AY5+AY6+AY8+AY9+AY11+AY12+AY14+AY15 -> 36.8
B12: Lavandería | C12: 1.8 | D12: - | G12: Closet de Limpieza | H12: 0.72 | I12: - | L12: Servicios higiénicos de adultos (1/2 baño acondicionado para personas con discapacidad) | M12: 4 | N12: - | Q12: Servicios higiénicos de adultos (1/2 baño acondicionado para personas con discapacidad) | R12: 4 | S12: - | V12: Closet para colchoneta | W12: 1 | X12: - | AA12: Closet para colchoneta | AB12: 1 | AC12: - | AF12: Closet para colchoneta | AG12: 1 | AH12: - | AK12: Closet para colchoneta | AL12: 1 | AM12: - | AO12: Cuidado diurno | AP12: A9 | AQ12: Closet para colchoneta | AV12: =+_xlfn.IFNA(VLOOKUP($AQ12,$V$4:$W$30,2,FALSE),"") -> 1 | AW12: =+_xlfn.IFNA(VLOOKUP($AQ12,$AA$4:$AB$30,2,FALSE),"") -> 1 | AX12: =+_xlfn.IFNA(VLOOKUP($AQ12,$AF$4:$AG$30,2,FALSE),"") -> 1 | AY12: =+_xlfn.IFNA(VLOOKUP($AQ12,$AK$4:$AL$30,2,FALSE),"") -> 1 | BE12: =SUM(BE3:BE11) -> 41.42
B13: Patio Tendal | C13: 8 | D13: - | G13: Lavandería | H13: 2.7 | I13: - | L13: Depósito de material educativo | M13: 6 | N13: - | Q13: Depósito de material educativo | R13: 6 | S13: - | V13: PLAZA DE USOS MULTIPLES/COMEDOR (mínimo 0.75 m2 por total de niños) | W13: 39 | X13: - | AA13: PLAZA DE USOS MULTIPLES/COMEDOR (mínimo 0.75 m2 por total de niños) | AB13: 45 | AC13: - | AF13: SALA MIXTA 4 | AG13: 31.2 | AH13: 12 | AK13: SALA MIXTA 4 | AL13: 50.4 | AM13: 20 | AO13: Cuidado diurno | AP13: A10 | AQ13: SALA MIXTA 4 | AX13: =+_xlfn.IFNA(VLOOKUP($AQ13,$AF$4:$AG$30,2,FALSE),"") -> 31.2 | AY13: =+_xlfn.IFNA(VLOOKUP($AQ13,$AK$4:$AL$30,2,FALSE),"") -> 50.4
B14: Espacio de juego al aire libre (mínimo 40% del área neta de las salas) | C14: 20.16 | G14: Patio Tendal | H14: 8 | I14: - | L14: Cubículo de Bomba de Agua | M14: 1.2 | N14: - | Q14: Cubículo de Bomba de Agua | R14: 1.2 | S14: - | U14: SERVICIOS COMPLEMENTARIOS | V14: Área de lavado de vajilla | W14: 2.7 | X14: - | Z14: SERVICIOS COMPLEMENTARIOS | AA14: Área de lavado de vajilla | AB14: 2.7 | AC14: - | AF14: Servicios Higiénicos (un inodoro y un lavatorio por cada 8 niños) incluye Pañalera. | AG14: 6.4 | AH14: - | AK14: Servicios Higiénicos (un inodoro y un lavatorio por cada 8 niños) incluye Pañalera | AL14: 8.2 | AM14: - | AO14: Cuidado diurno | AP14: A11 | AQ14: Servicios Higiénicos (un inodoro y un lavatorio por cada 8 niños) incluye Pañalera | AX14: =+AG14 -> 6.4 | AY14: =+_xlfn.IFNA(VLOOKUP($AQ14,$AK$4:$AL$30,2,FALSE),"") -> 8.2 | BB14: SALA MIXTA
G15: Espacio de juego al aire libre (mínimo 40% del área neta de las salas) | H15: 20.16 | L15: Closet de Limpieza | M15: 0.72 | N15: - | Q15: Closet de Limpieza | R15: 0.72 | S15: - | V15: Servicios higiénicos de adultos (1/2 baño acondicionado para personas con discapacidad) | W15: 4 | X15: - | AA15: Servicios higiénicos de adultos (1/2 baño acondicionado para personas con discapacidad) | AB15: 4 | AC15: - | AF15: Closet para colchoneta | AG15: 1 | AH15: - | AK15: Closet para colchoneta | AL15: 1 | AM15: - | AO15: Cuidado diurno | AP15: A12 | AQ15: Closet para colchoneta | AX15: =+_xlfn.IFNA(VLOOKUP($AQ15,$AF$4:$AG$30,2,FALSE),"") -> 1 | AY15: =+_xlfn.IFNA(VLOOKUP($AQ15,$AK$4:$AL$30,2,FALSE),"") -> 1 | BB15: Servicios Higiénicos (un inodoro y un lavatorio por cada 8 niños) incluye Pañalera
B16: Área Neta de Ambientes | C16: 72.12 | L16: Lavandería | M16: 2.7 | N16: - | Q16: Lavandería | R16: 2.7 | S16: - | V16: Depósito de material educativo | W16: 9 | X16: - | AA16: Depósito de material educativo | AB16: 9 | AC16: - | AF16: PLAZA DE USOS MULTIPLES/COMEDOR (mínimo 0.75 m2 por total de niños) | AG16: 54 | AH16: - | AK16: PLAZA DE USOS MULTIPLES/COMEDOR (mínimo 0.75 m2 por total de niños) | AL16: 60 | AM16: - | AO16: Cuidado diurno | AP16: A13 | AQ16: PLAZA DE USOS MULTIPLES/COMEDOR (mínimo 0.75 m2 por total de niños) | AS16: =+_xlfn.IFNA(VLOOKUP($AQ16,$G$4:$H$30,2,FALSE),"") -> 15 | AT16: =+_xlfn.IFNA(VLOOKUP($AQ16,$L$4:$M$30,2,FALSE),"") -> 24 | AU16: =+_xlfn.IFNA(VLOOKUP($AQ16,$Q$4:$R$30,2,FALSE),"") -> 30 | AV16: =+_xlfn.IFNA(VLOOKUP($AQ16,$V$4:$W$30,2,FALSE),"") -> 39 | AW16: =+_xlfn.IFNA(VLOOKUP($AQ16,$AA$4:$AB$30,2,FALSE),"") -> 45 | AX16: =+_xlfn.IFNA(VLOOKUP($AQ16,$AF$4:$AG$30,2,FALSE),"") -> 54 | AY16: =+_xlfn.IFNA(VLOOKUP($AQ16,$AK$4:$AL$30,2,FALSE),"") -> 60 | BB16: Closet para colchoneta
B17: % de circulación de muros (20%) | C17: 14.42 | G17: Área Neta de Ambientes | H17: 88.92 | L17: Patio Tendal | M17: 8 | N17: - | Q17: Patio Tendal | R17: 8 | S17: - | V17: Cubículo de Bomba de Agua | W17: 1.2 | X17: - | AA17: Cubículo de Bomba de Agua | AB17: 1.2 | AC17: - | AE17: SERVICIOS COMPLEMENTARIOS | AF17: Área de lavado de vajilla | AG17: 2.7 | AH17: - | AJ17: SERVICIOS COMPLEMENTARIOS | AK17: Área de lavado de vajilla | AL17: 2.7 | AM17: - | AO17: Servicios complementarios | AP17: A14 | AQ17: Área de lavado de vajilla | AR17: =+_xlfn.IFNA(VLOOKUP($AQ17,$B$4:$C$30,2,FALSE),"") -> 1.8 | AS17: =+_xlfn.IFNA(VLOOKUP($AQ17,$G$4:$H$30,2,FALSE),"") -> 2.7 | AT17: =+_xlfn.IFNA(VLOOKUP($AQ17,$L$4:$M$30,2,FALSE),"") -> 2.7 | AU17: =+_xlfn.IFNA(VLOOKUP($AQ17,$Q$4:$R$30,2,FALSE),"") -> 2.7 | AV17: =+_xlfn.IFNA(VLOOKUP($AQ17,$V$4:$W$30,2,FALSE),"") -> 2.7 | AW17: =+_xlfn.IFNA(VLOOKUP($AQ17,$AA$4:$AB$30,2,FALSE),"") -> 2.7 | AX17: =+_xlfn.IFNA(VLOOKUP($AQ17,$AF$4:$AG$30,2,FALSE),"") -> 2.7 | AY17: =+_xlfn.IFNA(VLOOKUP($AQ17,$AK$4:$AL$30,2,FALSE),"") -> 2.7 | BB17: Closet para colchoneta
B18: Área Techada Total | C18: 86.54 | G18: % de circulación de muros (20%) | H18: 17.78 | L18: Espacio de juego al aire libre (mínimo 40% del área neta de las salas) | M18: 32.64 | Q18: Espacio de juego al aire libre (mínimo 40% del área neta de las salas) | R18: 40.32 | V18: Closet de Limpieza | W18: 0.72 | X18: - | AA18: Closet de Limpieza | AB18: 0.72 | AC18: - | AF18: Servicios higiénicos de adultos (1/2 baño acondicionado para personas con discapacidad) | AG18: 4 | AH18: - | AK18: Servicios higiénicos de adultos (1/2 baño acondicionado para personas con discapacidad) | AL18: 4 | AM18: - | AO18: Servicios complementarios | AP18: A15 | AQ18: Servicios higiénicos de adultos (1/2 baño acondicionado para personas con discapacidad) | AR18: =+_xlfn.IFNA(VLOOKUP($AQ18,$B$4:$C$30,2,FALSE),"") -> 4 | AS18: =+_xlfn.IFNA(VLOOKUP($AQ18,$G$4:$H$30,2,FALSE),"") -> 4 | AT18: =+_xlfn.IFNA(VLOOKUP($AQ18,$L$4:$M$30,2,FALSE),"") -> 4 | AU18: =+_xlfn.IFNA(VLOOKUP($AQ18,$Q$4:$R$30,2,FALSE),"") -> 4 | AV18: =+_xlfn.IFNA(VLOOKUP($AQ18,$V$4:$W$30,2,FALSE),"") -> 4 | AW18: =+_xlfn.IFNA(VLOOKUP($AQ18,$AA$4:$AB$30,2,FALSE),"") -> 4 | AX18: =+_xlfn.IFNA(VLOOKUP($AQ18,$AF$4:$AG$30,2,FALSE),"") -> 4 | AY18: =+_xlfn.IFNA(VLOOKUP($AQ18,$AK$4:$AL$30,2,FALSE),"") -> 4 | BB18: PLAZA DE USOS MULTIPLES/COMEDOR (mínimo 0.75 m2 por total de niños)
B19: Área libre mínima (30% del área del terreno) | C19: 37.09 | G19: Área Techada Total | H19: 106.7 | V19: Lavandería | W19: 2.7 | X19: - | AA19: Lavandería | AB19: 2.7 | AC19: - | AF19: Depósito de material educativo | AG19: 12 | AH19: - | AK19: Depósito de material educativo | AL19: 12 | AM19: - | AO19: Servicios complementarios | AP19: A16 | AQ19: Depósito de material educativo | AR19: =+_xlfn.IFNA(VLOOKUP($AQ19,$B$4:$C$30,2,FALSE),"") -> 3 | AS19: =+_xlfn.IFNA(VLOOKUP($AQ19,$G$4:$H$30,2,FALSE),"") -> 3 | AT19: =+_xlfn.IFNA(VLOOKUP($AQ19,$L$4:$M$30,2,FALSE),"") -> 6 | AU19: =+_xlfn.IFNA(VLOOKUP($AQ19,$Q$4:$R$30,2,FALSE),"") -> 6 | AV19: =+_xlfn.IFNA(VLOOKUP($AQ19,$V$4:$W$30,2,FALSE),"") -> 9 | AW19: =+_xlfn.IFNA(VLOOKUP($AQ19,$AA$4:$AB$30,2,FALSE),"") -> 9 | AX19: =+_xlfn.IFNA(VLOOKUP($AQ19,$AF$4:$AG$30,2,FALSE),"") -> 12 | AY19: =+_xlfn.IFNA(VLOOKUP($AQ19,$AK$4:$AL$30,2,FALSE),"") -> 12 | BB19: Área de lavado de vajilla
B20: Área de Terreno mínima | C20: 123.63 | G20: Área libre mínima (30% del área del terreno) | H20: 45.73 | L20: Área Neta de Ambientes | M20: 139.52 | Q20: Área Neta de Ambientes | R20: 166.52 | V20: Patio Tendal | W20: 8 | X20: - | AA20: Patio Tendal | AB20: 8 | AC20: - | AF20: Cubículo de Bomba de Agua | AG20: 1.2 | AH20: - | AK20: Cubículo de Bomba de Agua | AL20: 1.2 | AM20: - | AO20: Servicios complementarios | AP20: A17 | AQ20: Cubículo de Bomba de Agua | AR20: =+_xlfn.IFNA(VLOOKUP($AQ20,$B$4:$C$30,2,FALSE),"") -> 1.2 | AS20: =+_xlfn.IFNA(VLOOKUP($AQ20,$G$4:$H$30,2,FALSE),"") -> 1.2 | AT20: =+_xlfn.IFNA(VLOOKUP($AQ20,$L$4:$M$30,2,FALSE),"") -> 1.2 | AU20: =+_xlfn.IFNA(VLOOKUP($AQ20,$Q$4:$R$30,2,FALSE),"") -> 1.2 | AV20: =+_xlfn.IFNA(VLOOKUP($AQ20,$V$4:$W$30,2,FALSE),"") -> 1.2 | AW20: =+_xlfn.IFNA(VLOOKUP($AQ20,$AA$4:$AB$30,2,FALSE),"") -> 1.2 | AX20: =+_xlfn.IFNA(VLOOKUP($AQ20,$AF$4:$AG$30,2,FALSE),"") -> 1.2 | AY20: =+_xlfn.IFNA(VLOOKUP($AQ20,$AK$4:$AL$30,2,FALSE),"") -> 1.2 | BB20: Servicios higiénicos de adultos (1/2 baño acondicionado para personas con discapacidad)
G21: Área de Terreno mínima | H21: 152.43 | L21: % de circulación de muros (20%) | M21: 27.9 | Q21: % de circulación de muros (20%) | R21: 33.3 | V21: Espacio de juego al aire libre (mínimo 40% del área neta de las salas) | W21: 52.8 | AA21: Espacio de juego al aire libre (mínimo 40% del área neta de las salas) | AB21: 60.48 | AC21: - | AF21: Closet de Limpieza | AG21: 0.72 | AH21: - | AK21: Closet de Limpieza | AL21: 0.72 | AM21: - | AO21: Servicios complementarios | AP21: A18 | AQ21: Closet de Limpieza | AR21: =+_xlfn.IFNA(VLOOKUP($AQ21,$B$4:$C$30,2,FALSE),"") -> 0.72 | AS21: =+_xlfn.IFNA(VLOOKUP($AQ21,$G$4:$H$30,2,FALSE),"") -> 0.72 | AT21: =+_xlfn.IFNA(VLOOKUP($AQ21,$L$4:$M$30,2,FALSE),"") -> 0.72 | AU21: =+_xlfn.IFNA(VLOOKUP($AQ21,$Q$4:$R$30,2,FALSE),"") -> 0.72 | AV21: =+_xlfn.IFNA(VLOOKUP($AQ21,$V$4:$W$30,2,FALSE),"") -> 0.72 | AW21: =+_xlfn.IFNA(VLOOKUP($AQ21,$AA$4:$AB$30,2,FALSE),"") -> 0.72 | AX21: =+_xlfn.IFNA(VLOOKUP($AQ21,$AF$4:$AG$30,2,FALSE),"") -> 0.72 | AY21: =+_xlfn.IFNA(VLOOKUP($AQ21,$AK$4:$AL$30,2,FALSE),"") -> 0.72 | BB21: Depósito de material educativo
L22: Área Techada Total | M22: 167.42 | Q22: Área Techada Total | R22: 199.82 | AF22: Lavandería | AG22: 2.7 | AH22: - | AK22: Lavandería | AL22: 2.7 | AM22: - | AO22: Servicios complementarios | AP22: A19 | AQ22: Lavandería | AR22: =+_xlfn.IFNA(VLOOKUP($AQ22,$B$4:$C$30,2,FALSE),"") -> 1.8 | AS22: =+_xlfn.IFNA(VLOOKUP($AQ22,$G$4:$H$30,2,FALSE),"") -> 2.7 | AT22: =+_xlfn.IFNA(VLOOKUP($AQ22,$L$4:$M$30,2,FALSE),"") -> 2.7 | AU22: =+_xlfn.IFNA(VLOOKUP($AQ22,$Q$4:$R$30,2,FALSE),"") -> 2.7 | AV22: =+_xlfn.IFNA(VLOOKUP($AQ22,$V$4:$W$30,2,FALSE),"") -> 2.7 | AW22: =+_xlfn.IFNA(VLOOKUP($AQ22,$AA$4:$AB$30,2,FALSE),"") -> 2.7 | AX22: =+_xlfn.IFNA(VLOOKUP($AQ22,$AF$4:$AG$30,2,FALSE),"") -> 2.7 | AY22: =+_xlfn.IFNA(VLOOKUP($AQ22,$AK$4:$AL$30,2,FALSE),"") -> 2.7 | BB22: Cubículo de Bomba de Agua
L23: Área libre mínima (30% del área del terreno) | M23: 71.15 | Q23: Área libre mínima (30% del área del terreno) | R23: 85.64 | V23: Área Neta de Ambientes | W23: 217.12 | AA23: Área Neta de Ambientes | AB23: 244.12 | AF23: Patio Tendal | AG23: 8 | AH23: - | AK23: Patio Tendal | AL23: 8 | AM23: - | AO23: Servicios complementarios | AP23: A20 | AQ23: Patio Tendal | AR23: =+_xlfn.IFNA(VLOOKUP($AQ23,$B$4:$C$30,2,FALSE),"") -> 8 | AS23: =+_xlfn.IFNA(VLOOKUP($AQ23,$G$4:$H$30,2,FALSE),"") -> 8 | AT23: =+_xlfn.IFNA(VLOOKUP($AQ23,$L$4:$M$30,2,FALSE),"") -> 8 | AU23: =+_xlfn.IFNA(VLOOKUP($AQ23,$Q$4:$R$30,2,FALSE),"") -> 8 | AV23: =+_xlfn.IFNA(VLOOKUP($AQ23,$V$4:$W$30,2,FALSE),"") -> 8 | AW23: =+_xlfn.IFNA(VLOOKUP($AQ23,$AA$4:$AB$30,2,FALSE),"") -> 8 | AX23: =+_xlfn.IFNA(VLOOKUP($AQ23,$AF$4:$AG$30,2,FALSE),"") -> 8 | AY23: =+_xlfn.IFNA(VLOOKUP($AQ23,$AK$4:$AL$30,2,FALSE),"") -> 8 | BB23: Closet de Limpieza
L24: Área de Terreno mínima | M24: 239.17 | Q24: Área de Terreno mínima | R24: 285.46 | V24: % de circulación de muros (20%) | W24: 43.42 | AA24: % de circulación de muros (20%) | AB24: 48.82 | AF24: Espacio de juego al aire libre (mínimo 40% del área neta de las salas) | AG24: 72.96 | AH24: - | AK24: Espacio de juego al aire libre (mínimo 40% del área neta de las salas) | AL24: 80.64 | AM24: - | AO24: Servicios complementarios | AP24: A21 | AQ24: Espacio de juego al aire libre (mínimo 40% del área neta de las salas) | AR24: =+_xlfn.IFNA(VLOOKUP($AQ24,$B$4:$C$30,2,FALSE),"") -> 20.16 | AS24: =+_xlfn.IFNA(VLOOKUP($AQ24,$G$4:$H$30,2,FALSE),"") -> 20.16 | AT24: =+_xlfn.IFNA(VLOOKUP($AQ24,$L$4:$M$30,2,FALSE),"") -> 32.64 | AU24: =+_xlfn.IFNA(VLOOKUP($AQ24,$Q$4:$R$30,2,FALSE),"") -> 40.32 | AV24: =+_xlfn.IFNA(VLOOKUP($AQ24,$V$4:$W$30,2,FALSE),"") -> 52.8 | AW24: =+_xlfn.IFNA(VLOOKUP($AQ24,$AA$4:$AB$30,2,FALSE),"") -> 60.48 | AX24: =+_xlfn.IFNA(VLOOKUP($AQ24,$AF$4:$AG$30,2,FALSE),"") -> 72.96 | AY24: =+_xlfn.IFNA(VLOOKUP($AQ24,$AK$4:$AL$30,2,FALSE),"") -> 80.64 | BB24: Lavandería
V25: Área Techada Total | W25: 260.54 | AA25: Área Techada Total | AB25: 292.94 | AR25: =+_xlfn.IFNA(VLOOKUP(AQ25,$B$4:$C$30,2,FALSE),"") | AS25: =+_xlfn.IFNA(VLOOKUP($AQ25,$G$4:$H$30,2,FALSE),"") | AT25: =+_xlfn.IFNA(VLOOKUP($AQ25,$L$4:$M$30,2,FALSE),"") | AU25: =+_xlfn.IFNA(VLOOKUP($AQ25,$Q$4:$R$30,2,FALSE),"") | AV25: =+_xlfn.IFNA(VLOOKUP($AQ25,$V$4:$W$30,2,FALSE),"") | AW25: =+_xlfn.IFNA(VLOOKUP($AQ25,$AA$4:$AB$30,2,FALSE),"") | AX25: =+_xlfn.IFNA(VLOOKUP($AQ25,$AF$4:$AG$30,2,FALSE),"") | AY25: =+_xlfn.IFNA(VLOOKUP($AQ25,$AK$4:$AL$30,2,FALSE),"")
V26: Área libre mínima (30% del área del terreno) | W26: 111.66 | AA26: Área libre mínima (30% del área del terreno) | AB26: 125.55 | AF26: Área Neta de Ambientes | AG26: 294.72 | AK26: Área Neta de Ambientes | AL26: 321.72 | AQ26: Área Neta de Ambientes | AR26: =+_xlfn.IFNA(VLOOKUP(AQ26,$B$4:$C$30,2,FALSE),"") -> 72.12 | AS26: =+_xlfn.IFNA(VLOOKUP($AQ26,$G$4:$H$30,2,FALSE),"") -> 88.92 | AT26: =+_xlfn.IFNA(VLOOKUP($AQ26,$L$4:$M$30,2,FALSE),"") -> 139.52 | AU26: =+_xlfn.IFNA(VLOOKUP($AQ26,$Q$4:$R$30,2,FALSE),"") -> 166.52 | AV26: =+_xlfn.IFNA(VLOOKUP($AQ26,$V$4:$W$30,2,FALSE),"") -> 217.12 | AW26: =+_xlfn.IFNA(VLOOKUP($AQ26,$AA$4:$AB$30,2,FALSE),"") -> 244.12 | AX26: =+_xlfn.IFNA(VLOOKUP($AQ26,$AF$4:$AG$30,2,FALSE),"") -> 294.72 | AY26: =+_xlfn.IFNA(VLOOKUP($AQ26,$AK$4:$AL$30,2,FALSE),"") -> 321.72
V27: Área de Terreno mínima | W27: 372.2 | AA27: Área de Terreno mínima | AB27: 418.49 | AF27: % de circulación de muros (20%) | AG27: 58.94 | AK27: % de circulación de muros (20%) | AL27: 64.34 | AQ27: % de circulación de muros (20%) | AR27: =+_xlfn.IFNA(VLOOKUP(AQ27,$B$4:$C$30,2,FALSE),"") -> 14.42 | AS27: =+_xlfn.IFNA(VLOOKUP($AQ27,$G$4:$H$30,2,FALSE),"") -> 17.78 | AT27: =+_xlfn.IFNA(VLOOKUP($AQ27,$L$4:$M$30,2,FALSE),"") -> 27.9 | AU27: =+_xlfn.IFNA(VLOOKUP($AQ27,$Q$4:$R$30,2,FALSE),"") -> 33.3 | AV27: =+_xlfn.IFNA(VLOOKUP($AQ27,$V$4:$W$30,2,FALSE),"") -> 43.42 | AW27: =+_xlfn.IFNA(VLOOKUP($AQ27,$AA$4:$AB$30,2,FALSE),"") -> 48.82 | AX27: =+_xlfn.IFNA(VLOOKUP($AQ27,$AF$4:$AG$30,2,FALSE),"") -> 58.94 | AY27: =+_xlfn.IFNA(VLOOKUP($AQ27,$AK$4:$AL$30,2,FALSE),"") -> 64.34
AF28: Área Techada Total | AG28: 353.66 | AK28: Área Techada Total | AL28: 385.06 | AQ28: Área Techada Total | AR28: =+_xlfn.IFNA(VLOOKUP(AQ28,$B$4:$C$30,2,FALSE),"") -> 86.54 | AS28: =+_xlfn.IFNA(VLOOKUP($AQ28,$G$4:$H$30,2,FALSE),"") -> 106.7 | AT28: =+_xlfn.IFNA(VLOOKUP($AQ28,$L$4:$M$30,2,FALSE),"") -> 167.42 | AU28: =+_xlfn.IFNA(VLOOKUP($AQ28,$Q$4:$R$30,2,FALSE),"") -> 199.82 | AV28: =+_xlfn.IFNA(VLOOKUP($AQ28,$V$4:$W$30,2,FALSE),"") -> 260.54 | AW28: =+_xlfn.IFNA(VLOOKUP($AQ28,$AA$4:$AB$30,2,FALSE),"") -> 292.94 | AX28: =+_xlfn.IFNA(VLOOKUP($AQ28,$AF$4:$AG$30,2,FALSE),"") -> 353.66 | AY28: =+_xlfn.IFNA(VLOOKUP($AQ28,$AK$4:$AL$30,2,FALSE),"") -> 385.06
AF29: Área libre mínima (30% del área del terreno) | AG29: 151.57 | AK29: Área libre mínima (30% del área del terreno) | AL29: 165.45 | AO29: 0.428 | AQ29: Área libre mínima (30% del área del terreno) | AR29: =+_xlfn.IFNA(VLOOKUP(AQ29,$B$4:$C$30,2,FALSE),"") -> 37.09 | AS29: =+_xlfn.IFNA(VLOOKUP($AQ29,$G$4:$H$30,2,FALSE),"") -> 45.73 | AT29: =+_xlfn.IFNA(VLOOKUP($AQ29,$L$4:$M$30,2,FALSE),"") -> 71.15 | AU29: =+_xlfn.IFNA(VLOOKUP($AQ29,$Q$4:$R$30,2,FALSE),"") -> 85.64 | AV29: =+_xlfn.IFNA(VLOOKUP($AQ29,$V$4:$W$30,2,FALSE),"") -> 111.66 | AW29: =+_xlfn.IFNA(VLOOKUP($AQ29,$AA$4:$AB$30,2,FALSE),"") -> 125.55 | AX29: =+_xlfn.IFNA(VLOOKUP($AQ29,$AF$4:$AG$30,2,FALSE),"") -> 151.57 | AY29: =+_xlfn.IFNA(VLOOKUP($AQ29,$AK$4:$AL$30,2,FALSE),"") -> 165.45
AF30: Área de Terreno mínima | AG30: 505.23 | AK30: Área de Terreno mínima | AL30: 551.51 | AQ30: Área de Terreno mínima | AR30: =+_xlfn.IFNA(VLOOKUP(AQ30,$B$4:$C$30,2,FALSE),"") -> 123.63 | AS30: =+_xlfn.IFNA(VLOOKUP($AQ30,$G$4:$H$30,2,FALSE),"") -> 152.43 | AT30: =+_xlfn.IFNA(VLOOKUP($AQ30,$L$4:$M$30,2,FALSE),"") -> 239.17 | AU30: =+_xlfn.IFNA(VLOOKUP($AQ30,$Q$4:$R$30,2,FALSE),"") -> 285.46 | AV30: =+_xlfn.IFNA(VLOOKUP($AQ30,$V$4:$W$30,2,FALSE),"") -> 372.2 | AW30: =+_xlfn.IFNA(VLOOKUP($AQ30,$AA$4:$AB$30,2,FALSE),"") -> 418.49 | AX30: =+_xlfn.IFNA(VLOOKUP($AQ30,$AF$4:$AG$30,2,FALSE),"") -> 505.23 | AY30: =+_xlfn.IFNA(VLOOKUP($AQ30,$AK$4:$AL$30,2,FALSE),"") -> 551.51
AR38: Tipo I-A | AS38: Tipo I-B | AT38: Tipo II-A | AU38: Tipo II-B | AV38: Tipo III-A | AW38: Tipo III-B | AX38: Tipo IV-A | AY38: Tipo IV-B
AQ39: Capacidad de atención (niños y niñas) | AR39: 20 | AS39: 20 | AT39: 32 | AU39: 40 | AV39: 52 | AW39: 60 | AX39: 72 | AY39: 82
AQ40: =+AQ30 -> Área de Terreno mínima | AR40: 123.63 | AS40: 152.43 | AT40: 239.17 | AU40: 285.46 | AV40: 372.2 | AW40: 418.49 | AX40: 505.23 | AY40: 551.51
AT41: Área insuficiente | AV41: 0 | AW41: Área insuficiente
AS42: 20 | AT42: Tipo I-A | AV42: 123.63 | AW42: Tipo I-A | AX42: 1
AS43: 20 | AT43: Tipo I-B | AV43: 152.43 | AW43: Tipo I-B | AX43: 2
AS44: 32 | AT44: Tipo II-A | AV44: 239.17 | AW44: Tipo II-A | AX44: 3
AS45: 40 | AT45: Tipo II-B | AV45: 285.46 | AW45: Tipo II-B | AX45: 4
AS46: 52 | AT46: Tipo III-A | AV46: 372.2 | AW46: Tipo III-A | AX46: 5
AS47: 60 | AT47: Tipo III-B | AV47: 418.49 | AW47: Tipo III-B | AX47: 6
...

Sheet Datos Generales
B2: SECCIÓN N°01: DATOS GENERALES DEL PROYECTO
B4: 1.01 Institucionalidad
B6: UNIDAD FORMULADORA (UF)
B8: Nivel de gobierno :
B10: Entidad :
B12: Nombre de la UF:
B14: Responsable de la UF:
B16: UNIDAD EJECUTORA DE INVERSIONES (UEI)
B18: Nivel de gobierno :
B20: Entidad :
B22: Nombre de la UEI:
B24: Responsable de la UEI:
B27: 1.02 Responsabilidad funcional y tipología del proyecto de inversión
B29: Función | H29: 23 PROTECCIÓN SOCIAL
B31: División funcional | H31: 051 ASISTENCIA SOCIAL
B33: Grupo funcional | H33: 0115 PROTECCIÓN DE POBLACIONES EN RIESGO
B35: Sector responsable | H35: DESARROLLO E INCLUSION SOCIAL
B37: Tipología de proyecto | H37: CENTRO INFANTIL DE ATENCIÓN INTEGRAL
B40: 1.03 Nombre del proyecto de inversión
B42: Naturaleza de intervención | F42: Objeto de intervención | K42: Localización
F44: =+IF(B44="","","del Servicio de Cuidado Infantil en el Centro Infantil de Atención Integral (CIAI)") | K44: =+IF(B44="","","en la localidad de "&'Unidad Productora'!L20&", distrito de "&'Unidad Productora'!J20&", provincia de "&'Unidad Productora'!H20&", departamento de "&'Unidad Productora'!E20)
B47: 1.04 Alineamiento y contribución al cierre de una brecha prioritaria
B49: Servicios públicos con brecha identificada y priorizada | M49: =+IF(B44="","","Servicio de cuidado diurno")
B51: Nombre del Indicador de brecha de acceso a servicios | J51: Unidad de medida | N51: Espacio geográfico | R51: Año | T51: Valor
B53: =+'Problema-Objetivo'!F8 | J53: =+IF(B44="","","Centro Infantil de Atención Integral (CIAI)") | N53: =+IF(B44="","","Distrito de "&'Unidad Productora'!J20) | R53: =IF(B44="","",TODAY())
B55: Contribución del Cierre de Brecha (Valor) | F55: Valor:

Sheet Territorio
B2: SECCIÓN N°02: DIAGNÓSTICO DEL TERRITORIO
B4: 2.01 Localización del área de estudio del proyecto
B6: N° | C6: Ubigeo | G6: Departamento | K6: Provincia | L6: Provincia | O6: Distrito | S6: Localidad/Centro poblado
B7: 1 | G7: =+IF(C7="","",VLOOKUP(C7,UBIGEO,4,FALSE)) | K7: =+IF(C7="","",VLOOKUP(C7,UBIGEO,3,FALSE)) | O7: =+IF(C7="","",VLOOKUP(C7,UBIGEO,2,FALSE))
B8: 2 | G8: =+IF(C8="","",VLOOKUP(C8,UBIGEO,4,FALSE)) | K8: =+IF(C8="","",VLOOKUP(C8,UBIGEO,3,FALSE)) | O8: =+IF(C8="","",VLOOKUP(C8,UBIGEO,2,FALSE))
B9: 3 | G9: =+IF(C9="","",VLOOKUP(C9,UBIGEO,4,FALSE)) | K9: =+IF(C9="","",VLOOKUP(C9,UBIGEO,3,FALSE)) | O9: =+IF(C9="","",VLOOKUP(C9,UBIGEO,2,FALSE))
B10: 4 | G10: =+IF(C10="","",VLOOKUP(C10,UBIGEO,4,FALSE)) | K10: =+IF(C10="","",VLOOKUP(C10,UBIGEO,3,FALSE)) | O10: =+IF(C10="","",VLOOKUP(C10,UBIGEO,2,FALSE))
B11: 5 | G11: =+IF(C11="","",VLOOKUP(C11,UBIGEO,4,FALSE)) | K11: =+IF(C11="","",VLOOKUP(C11,UBIGEO,3,FALSE)) | O11: =+IF(C11="","",VLOOKUP(C11,UBIGEO,2,FALSE))
B12: Nota: Considerar el espacio geográfico donde se localiza la población afectada y el área donde se ubica el CIAI
B15: 2.02 Localización del área de influencia del proyecto
B17: N° | C17: Ubigeo | G17: Departamento | K17: Provincia | L17: Provincia | O17: Distrito | S17: Localidad/Centro poblado
B18: 1 | G18: =+IF(C18="","",VLOOKUP(C18,UBIGEO,4,FALSE)) | K18: =+IF(C18="","",VLOOKUP(C18,UBIGEO,3,FALSE)) | O18: =+IF(C18="","",VLOOKUP(C18,UBIGEO,2,FALSE))
B19: 2 | G19: =+IF(C19="","",VLOOKUP(C19,UBIGEO,4,FALSE)) | K19: =+IF(C19="","",VLOOKUP(C19,UBIGEO,3,FALSE)) | O19: =+IF(C19="","",VLOOKUP(C19,UBIGEO,2,FALSE))
B20: 3 | G20: =+IF(C20="","",VLOOKUP(C20,UBIGEO,4,FALSE)) | K20: =+IF(C20="","",VLOOKUP(C20,UBIGEO,3,FALSE)) | O20: =+IF(C20="","",VLOOKUP(C20,UBIGEO,2,FALSE))
B21: 4 | G21: =+IF(C21="","",VLOOKUP(C21,UBIGEO,4,FALSE)) | K21: =+IF(C21="","",VLOOKUP(C21,UBIGEO,3,FALSE)) | O21: =+IF(C21="","",VLOOKUP(C21,UBIGEO,2,FALSE))
B22: 5 | G22: =+IF(C22="","",VLOOKUP(C22,UBIGEO,4,FALSE)) | K22: =+IF(C22="","",VLOOKUP(C22,UBIGEO,3,FALSE)) | O22: =+IF(C22="","",VLOOKUP(C22,UBIGEO,2,FALSE))
B23: Nota: Considerar el espacio geográfico donde se ubica la población afectada
B26: 2.03 Macro y micro localización del área de estudio
R28: =+"Leyenda Mapa de macrolocalización del CIAI de la localidad/centro poblado de "&S7&", del distrito de "&O7&", provincia de "&K7&", departamento de "&G7 -> Leyenda Mapa de macrolocalización del CIAI de la localidad/centro poblado de , del distrito de , provincia de , departamento de
B29: Nota: Para la macrolocalización, puede utilizar la fuente: | J29: https://estadist.inei.gob.pe/map
J30: https://www.cunamas.gob.pe/inicio/cobertura-de-servicios/
R32: =+"Leyenda Mapa de microlocalización del CIAI de la localidad/centro poblado de "&S7&", del distrito de "&O7&", provincia de "&K7&", departamento de "&G7 -> Leyenda Mapa de microlocalización del CIAI de la localidad/centro poblado de , del distrito de , provincia de , departamento de
B33: Fuente de información:
B34: Nota: Para la microlocalización, puede utilizar las fuentes: | J34: https://earth.google.com/web/
J35: https://www.cunamas.gob.pe/inicio/cobertura-de-servicios/
B37: 2.04 Análisis de las características del distrito donde se ubica o ubicará el CIAI
B39: A. Datos generales del distrito
B40: Altitud | E40: Temperatura media anual | I40: Humedad | L40: Precipitación media anual | O40: Coordenadas geográficas en decimales Latitud y Longitud.
B43: Fuente: | E43: https://www.senamhi.gob.pe/?&p=estaciones
B45: B. Características de: i) accesibilidad al distrito; ii) condiciones de pobreza; y, iii) principales características sociales y económicas
B46: Accesibilidad
B48: Condiciones de pobreza
B50: Principales características sociales y económicas
B53: C. Acceso a servicios públicos en el distrito
B54: Servicio público | H54: Porcentaje de viviendas con acceso | L54: Año de información | O54: Fuente de información (incluir enlace)
B55: Abastecimiento de agua por red pública dentro de la vivienda
B56: Servicio higiénico conectado a red pública de desagüe dentro de la vivienda
B57: Cuenta con alumbrado eléctrico conectado a una red pública
B58: Cuenta con servicio de internet
B59: Fuente: | H59: https://censos2017.inei.gob.pe/redatam/
...

Sheet Unidad Productora
B2: SECCIÓN N°03: DIAGNÓSTICO DE LA UNIDAD PRODUCTORA
B4: LA UNIDAD PRODUCTORA DE BIENES Y SERVICIOS
B7: 3.01 Nombre de la Unidad Productora:
B12: 3.02 Código de identificación del CIAI (Local ID) y tipo de CIAI
C14: Código de CIAI
B17: 3.03 Localización geográfica de la Unidad Productora
B19: N° | C19: UBIGEO | E19: Departamento | H19: Provincia | J19: Distrito | L19: Localidad / Centro poblado | N19: Coordenadas geográficas en decimales Latitud y Longitud.
B20: 1 | E20: =+IF(C20="","",VLOOKUP(C20,UBIGEO,4,FALSE)) | H20: =+IF(C20="","",VLOOKUP(C20,UBIGEO,3,FALSE)) | J20: =+IF(C20="","",VLOOKUP(C20,UBIGEO,2,FALSE))
B21: Nota: Para buscar las coordenadas geográficas, puede utilizar la fuente: | L21: https://www.google.com/maps
B24: 3.04 Diagnóstico de procesos de la Unidad Productora
B26: N° | C26: Caracterización de los procesos de producción del CIAI
C27: Servicio y sus procesos de producción | F27: Descripción ¿En qué consiste el proceso? | I27: Situación actual
B28: 1 | C28: Servicio de cuidado diurno | D28: Aprendizaje Infantil: Cuidado y Juego | F28: Consiste en fortalecer las habilidades sensoriales, motrices, comunicativas, cognitivas y socioemocionales de las niñas y los niños, que les permite el desarrollo de su identidad, autonomía, lenguaje, pensamiento y adaptación al medio, protegiéndoles de los posibles efectos de entornos adversos a su desarrollo. | R28: Anexo: informe técnico de la situación actual - contenido mínimo
B29: 2 | D29: Cuidado de la salud infantil en el CIAI | F29: Consiste en brindar cuidados a las niñas/niños en el CIAI como el lavado de manos, la higiene bucal, el uso y consumo de agua segura, el suministro de suplementos con hierro, la lactancia materna, como estrategias de prevención de la enfermedad y promoción de la salud. Asimismo, fortalece en las niñas y los niños la autonomía como en el control de esfínteres, descanso y sueño, cambio de ropa, orden del ambiente, entre otros, según el desarrollo y la edad de la niña y el niño.
B30: 3 | D30: Atención alimentaria y nutricional | F30: Consiste en atender las necesidades básicas de alimentación y nutrición mediante la dotación de una alimentación balanceada, saludable e inocua, de acuerdo a sus necesidades nutricionales según grupo etario de las niñas y los niños, que contribuyen con un adecuado estado nutricional para favorecer su óptimo crecimiento y desarrollo.
B31: 4 | D31: Fortalecimiento de Prácticas de cuidado saludable y aprendizaje en la familia usuaria | F31: Consiste en fortalecer las prácticas de cuidado saludable y aprendizaje (interacción, juego y comunicación) de la madre, padre u otro/a cuidador/a principal que permita dar una respuesta flexible, adecuada y pertinente de acuerdo a las necesidades e intereses de las niñas y los niños, a fin de favorecer su desarrollo integral. En las actividades se promueve la participación de uno o más miembros de la familia se encargan o son responsables del cuidado de la niña o el niño.
B32: Nota: Incluir informe de situación actual de las condiciones en las que se brinda el servicio
B35: 3.05 Diagnóstico de los activos de la UP
B38: Servicio y procesos de producción | D38: Tipo de Factor productivo | E38: Activos estratégicos | G38: Cumple con los estándares de calidad del PNCM | J38: Estado Situacional
G39: Norma técnica | I39: Sí / No
B41: Servicio de cuidado diurno: Procesos: 1. Aprendizaje Infantil 2. Cuidado y JuegoCuidado de la salud infantil en el CIAI 3. Atención alimentaria y nutricional 4. Fortalecimiento de Prácticas de cuidado saludable y aprendizaje en la familia usuaria | D41: Infraestructura | E41: Sala de cuidado diurno
E42: Sala de usos múltiples
E43: Ambiente de recreación activa
E44: Ambiente de servicios generales
E45: Ambiente de preparación y expendio de alimentos
E46: Almacén
E47: Cerco perimétrico
E48: Muro de contención
D49: Mobiliario | E49: Mobiliario de sala de cuidado diurno
